Workbook

Sheet book_raw
A1: book_id | B1: read_order | C1: book_title | D1: author_first_name | E1: author_last_name | F1: book_genre | G1: format | H1: language | I1: pages | J1: month_read | K1: rating | L1: owned | M1: series_number | N1: series_name | O1: year_published | P1: has_quotes | Q1: top_book
A2: {=ROW()-ROW(main_table[#Headers])} -> 1 | B2: 1 | C2: Читець | D2: Бернхард | E2: Шлінк | F2: роман | G2: Print | H2: Ukrainian | I2: 189 | J2: January | K2: 5 | L2: yes | O2: 1995 | P2: yes | Q2: +
A3: {=ROW()-ROW(main_table[#Headers])} -> 2 | B3: 2 | C3: Емоційний інтелект у дитини | D3: Джон, Джоан | E3: Готтман, Деклер | F3: психологія | G3: Print | H3: Ukrainian | I3: 272 | J3: January | K3: 5 | L3: no | O3: 1997 | P3: yes
A4: {=ROW()-ROW(main_table[#Headers])} -> 3 | B4: 3 | C4: Ми, живі | D4: Айн | E4: Ренд | F4: історичний роман | G4: Print | H4: Ukrainian | I4: 504 | J4: January | K4: 5 | L4: yes | O4: 1936 | P4: yes | Q4: +
A5: {=ROW()-ROW(main_table[#Headers])} -> 4 | B5: 4 | C5: The secret garden | D5: Frances Hodgson | E5: Burnett | F5: дитяча новела | G5: Print | H5: English | I5: 288 | J5: January | K5: 4 | L5: yes | O5: 1910 | P5: yes
A6: {=ROW()-ROW(main_table[#Headers])} -> 5 | B6: 5 | C6: Необхідне зло | D6: Абір | E6: Мухерджі | F6: детектив | G6: Audio | H6: Ukrainian | I6: 400 | J6: January | K6: 5 | L6: no | M6: 2 | N6: капітан Віндгем та сержант Бенерджі | O6: 2017 | P6: yes
A7: {=ROW()-ROW(main_table[#Headers])} -> 6 | B7: 6 | C7: Незриме життя Адді Лярю | D7: Вікторія | E7: Шваб | F7: історичне фентезі | G7: Ebook | H7: Ukrainian | I7: 544 | J7: February | K7: 4 | L7: yes | O7: 2020 | P7: yes
A8: {=ROW()-ROW(main_table[#Headers])} -> 7 | B8: 7 | C8: Дим і попіл | D8: Абір | E8: Мухерджі | F8: детектив | G8: Audio | H8: Ukrainian | I8: 352 | J8: February | K8: 5 | L8: no | M8: 3 | N8: капітан Віндгем та сержант Бенерджі | O8: 2018 | P8: no
A9: {=ROW()-ROW(main_table[#Headers])} -> 8 | B9: 8 | C9: Дім голосів | D9: Донато | E9: Каррізі | F9: психологічний трилер | G9: Ebook | H9: Ukrainian | I9: 304 | J9: February | K9: 5 | L9: yes | M9: 1 | N9: Слідство П'єтро Джербера | O9: 2019 | P9: yes | Q9: +
A10: {=ROW()-ROW(main_table[#Headers])} -> 9 | B10: 9 | C10: Машина часу | D10: Герберт | E10: Веллс | F10: науково-фантастичний роман | G10: Audio | H10: Ukrainian | I10: 240 | J10: February | K10: 4 | L10: no | O10: 1888 | P10: yes
A11: {=ROW()-ROW(main_table[#Headers])} -> 10 | B11: 10 | C11: Холлі | D11: Стівен | E11: Кінг | F11: детектив | G11: Ebook | H11: Ukrainian | I11: 608 | J11: February | K11: 5 | L11: yes | O11: 2023 | P11: yes | Q11: +
A12: {=ROW()-ROW(main_table[#Headers])} -> 11 | B12: 11 | C12: Червоні лубутени | D12: Джоджо | E12: Мойєс | F12: любовний роман | G12: Ebook | H12: Ukrainian | I12: 448 | J12: February | K12: 5 | L12: yes | O12: 2023 | P12: yes | Q12: +
A13: {=ROW()-ROW(main_table[#Headers])} -> 12 | B13: 12 | C13: Список бажань | D13: Йон | E13: Колфер | F13: фантастична повість | G13: Audio | H13: Ukrainian | I13: 288 | J13: February | K13: 5 | L13: no | O13: 2007 | P13: no
A14: {=ROW()-ROW(main_table[#Headers])} -> 13 | B14: 13 | C14: Північний вітер | D14: Даніель | E14: Глаттауер | F14: роман | G14: Audio | H14: Ukrainian | I14: 192 | J14: March | K14: 3 | L14: no | O14: 2006 | P14: no
A15: {=ROW()-ROW(main_table[#Headers])} -> 14 | B15: 14 | C15: Смерть на Сході | D15: Абір | E15: Мухерджі | F15: детектив | G15: Audio | H15: Ukrainian | I15: 400 | J15: March | K15: 4 | L15: no | M15: 4 | N15: капітан Віндгем та сержант Бенерджі | O15: 2019 | P15: yes
A16: {=ROW()-ROW(main_table[#Headers])} -> 15 | B16: 15 | C16: Крамничка на розі | D16: Джоджо | E16: Мойєс | F16: любовний роман | G16: Ebook | H16: Ukrainian | I16: 480 | J16: March | K16: 3 | L16: yes | O16: 2005 | P16: yes
A17: {=ROW()-ROW(main_table[#Headers])} -> 16 | B17: 16 | C17: Бальзам для душі | D17: Норберт | E17: Лехляйтнер | F17: релігія, християнство | G17: Print | H17: Ukrainian | I17: 188 | J17: March | K17: 4 | L17: no | O17: 2022 | P17: yes
A18: {=ROW()-ROW(main_table[#Headers])} -> 17 | B18: 17 | C18: Червоний дракон | D18: Томас | E18: Гарріс | F18: жахи, трилер | G18: Audio | H18: Ukrainian | I18: 400 | J18: March | K18: 5 | L18: no | M18: 1 | N18: Ганнібал Лектер | O18: 1981 | P18: yes | Q18: +
A19: {=ROW()-ROW(main_table[#Headers])} -> 18 | B19: 18 | C19: Мовчання ягнят | D19: Томас | E19: Гарріс | F19: жахи, трилер | G19: Audio | H19: Ukrainian | I19: 338 | J19: March | K19: 5 | L19: no | M19: 2 | N19: Ганнібал Лектер | O19: 1988 | P19: yes | Q19: +
A20: {=ROW()-ROW(main_table[#Headers])} -> 19 | B20: 19 | C20: Часосховище | D20: Георгі | E20: Господінов | F20: роман | G20: Ebook | H20: Ukrainian | I20: 360 | J20: March | K20: 3 | L20: yes | O20: 2020 | P20: yes
A21: {=ROW()-ROW(main_table[#Headers])} -> 20 | B21: 20 | C21: Ганнібал | D21: Томас | E21: Гарріс | F21: жахи, трилер | G21: Audio | H21: Ukrainian | I21: 512 | J21: March | K21: 5 | L21: no | M21: 3 | N21: Ганнібал Лектер | O21: 1999 | P21: yes | Q21: +
A22: {=ROW()-ROW(main_table[#Headers])} -> 21 | B22: 21 | C22: Сходження Ганнібала | D22: Томас | E22: Гарріс | F22: жахи, трилер | G22: Audio | H22: Ukrainian | I22: 288 | J22: April | K22: 5 | L22: no | M22: 4 | N22: Ганнібал Лектер | O22: 2006 | P22: yes | Q22: +
A23: {=ROW()-ROW(main_table[#Headers])} -> 22 | B23: 22 | C23: Четверте крило | D23: Ребекка | E23: Яррос | F23: романтичне фентезі | G23: Audio | H23: Ukrainian | I23: 528 | J23: April | K23: 4 | L23: no | M23: 1 | N23: Емпіреї | O23: 2023 | P23: no
A24: {=ROW()-ROW(main_table[#Headers])} -> 23 | B24: 23 | C24: Смарагдове небо | D24: Ілона | E24: Верхівська-Ельтек | F24: поезія | G24: Print | H24: Ukrainian | I24: 412 | J24: April | K24: 4 | L24: no | O24: 2024 | P24: no
A25: {=ROW()-ROW(main_table[#Headers])} -> 24 | B25: 24 | C25: Дев'ять життів Крістофера Чанта | D25: Діана Вінн | E25: Джонс | F25: дитяче фентезі | G25: Ebook | H25: Ukrainian | I25: 358 | J25: April | K25: 4 | L25: no | O25: 1988 | P25: yes
A26: {=ROW()-ROW(main_table[#Headers])} -> 25 | B26: 25 | C26: Залізне полум'я | D26: Ребекка | E26: Яррос | F26: романтичне фентезі | G26: Audio | H26: Ukrainian | I26: 623 | J26: April | K26: 4 | L26: no | M26: 2 | N26: Емпіреї | O26: 2023 | P26: no
A27: {=ROW()-ROW(main_table[#Headers])} -> 26 | B27: 26 | C27: Поглиначі мертвих | D27: Майкл | E27: Крайтон | F27: історичний роман | G27: Ebook | H27: Ukrainian | I27: 272 | J27: April | K27: 5 | L27: yes | O27: 1976 | P27: yes | Q27: +
A28: {=ROW()-ROW(main_table[#Headers])} -> 27 | B28: 27 | C28: Типу Б'юїк 8 | D28: Стівен | E28: Кінг | F28: фантастика; жахи | G28: Audio | H28: Ukrainian | I28: 496 | J28: April | K28: 4 | L28: no | O28: 2002 | P28: no
A29: {=ROW()-ROW(main_table[#Headers])} -> 28 | B29: 28 | C29: Родаки | D29: Дмитро | E29: Кешеля | F29: роман-колаж | G29: Audio | H29: Ukrainian | I29: 384 | J29: April | K29: 4 | L29: no | O29: 2016 | P29: no
A30: {=ROW()-ROW(main_table[#Headers])} -> 29 | B30: 29 | C30: Штормовий фронт | D30: Джим | E30: Бутчер | F30: міське детективне фентезі | G30: Audio | H30: Ukrainian | I30: 322 | J30: May | K30: 4 | L30: no | M30: 1 | N30: Справи Дрездена | O30: 2000 | P30: no
A31: {=ROW()-ROW(main_table[#Headers])} -> 30 | B31: 30 | C31: Невгамовні мерці | D31: Саймон | E31: Бекетт | F31: детективний трилер | G31: Print | H31: Ukrainian | I31: 496 | J31: May | K31: 5 | L31: yes | M31: 5 | N31: Девід Хантер | O31: 2017 | P31: yes | Q31: +
A32: {=ROW()-ROW(main_table[#Headers])} -> 31 | B32: 31 | C32: Безрозсудний місяць | D32: Джим | E32: Бутчер | F32: міське детективне фентезі | G32: Audio | H32: Ukrainian | I32: 352 | J32: May | K32: 4 | L32: no | M32: 2 | N32: Справи Дрездена | O32: 2001 | P32: no
A33: {=ROW()-ROW(main_table[#Headers])} -> 32 | B33: 32 | C33: Смертельна небезпека | D33: Джим | E33: Бутчер | F33: міське детективне фентезі | G33: Audio | H33: Ukrainian | I33: 378 | J33: May | K33: 4 | L33: no | M33: 3 | N33: Справи Дрездена | O33: 2001 | P33: no
A34: {=ROW()-ROW(main_table[#Headers])} -> 33 | B34: 33 | C34: Палюче тепло вб'є нас найперше | D34: Джефф | E34: Гуделл | F34: наук-поп | G34: Print | H34: Ukrainian | I34: 368 | J34: May | K34: 5 | L34: yes | O34: 2024 | P34: yes
A35: {=ROW()-ROW(main_table[#Headers])} -> 34 | B35: 34 | C35: Зоряні війни: Стара Республіка: Реван | D35: Дрю | E35: Карпишин | F35: наукова фантастика | G35: Audio | H35: Ukrainian | I35: 320 | J35: May | K35: 5 | L35: no | O35: 2011 | P35: no | Q35: +
A36: {=ROW()-ROW(main_table[#Headers])} -> 35 | B36: 35 | C36: Війна з саламандрами | D36: Карел | E36: Чапек | F36: фантастика; антиутопія | G36: Audio | H36: Ukrainian | I36: 256 | J36: June | K36: 5 | L36: no | O36: 1936 | P36: no | Q36: +
A37: {=ROW()-ROW(main_table[#Headers])} -> 36 | B37: 36 | C37: Запах смерті | D37: Саймон | E37: Бекетт | F37: детективний трилер | G37: Print | H37: Ukrainian | I37: 368 | J37: June | K37: 5 | L37: yes | M37: 6 | N37: Девід Хантер | O37: 2019 | P37: no | Q37: +
A38: {=ROW()-ROW(main_table[#Headers])} -> 37 | B38: 37 | C38: Гаррі Поттер і методи раціональності | D38: Еліезер | E38: Юдковський | F38: фентезі; фанфік | G38: Audio | H38: Ukrainian | I38: 2184 | J38: June | K38: 5 | L38: no | M38: 1 | N38: Гаррі Поттер (фанфік) | O38: 2010 | P38: no
A39: {=ROW()-ROW(main_table[#Headers])} -> 38 | B39: 38 | C39: Гаррі Поттер та ігри професора | D39: Еліезер | E39: Юдковський | F39: фентезі; фанфік | G39: Audio | H39: Ukrainian | I39: 1649 | J39: June | K39: 5 | L39: no | M39: 2 | N39: Гаррі Поттер (фанфік) | P39: no
A40: {=ROW()-ROW(main_table[#Headers])} -> 39 | B40: 39 | C40: Соляріс | D40: Станіслав | E40: Лем | F40: науково-фантастичний роман | G40: Audio | H40: Ukrainian | I40: 352 | J40: June | K40: 5 | L40: no | O40: 1961 | P40: no
...

Sheet quotes
A1: Book_ID | B1: read_order | C1: book_title | D1: quote_text
A2: =IF(quotes_table[[#This Row],[ read_order]] = "","",INDEX(main_table[book_id],quotes_table[[#This Row],[ read_order]])) -> 1 | B2: 1 | C2: =IF(quotes_table[[#This Row],[ read_order]] = "","",INDEX(main_table[book_title],quotes_table[[#This Row],[ read_order]])) -> Читець | D2: Коли людина прогавила слушну мить, коли надто довго не може чогось досягти, коли їй задовго відмовляють у чомусь, потім усе з'являється запізно, навіть якщо вона нарешті виборює все своїми зусиллями і з радістю сприймає здобутки.
A3: =IF(quotes_table[[#This Row],[ read_order]] = "","",INDEX(main_table[book_id],quotes_table[[#This Row],[ read_order]])) -> 2 | B3: 2 | C3: =IF(quotes_table[[#This Row],[ read_order]] = "","",INDEX(main_table[book_title],quotes_table[[#This Row],[ read_order]])) -> Емоційний інтелект у дитини | D3: Мета емоційного виховання в тому, щоб вивчити й зрозуміти емоції, а не придушити їх.
A4: =IF(quotes_table[[#This Row],[ read_order]] = "","",INDEX(main_table[book_id],quotes_table[[#This Row],[ read_order]])) -> 2 | B4: 2 | C4: =IF(quotes_table[[#This Row],[ read_order]] = "","",INDEX(main_table[book_title],quotes_table[[#This Row],[ read_order]])) -> Емоційний інтелект у дитини | D4: Емоційне виховання має на меті глибший рівень емпатії та можливості вислухати. Будьте союзником дитини, коли вона приходить по допомогу.
A5: =IF(quotes_table[[#This Row],[ read_order]] = "","",INDEX(main_table[book_id],quotes_table[[#This Row],[ read_order]])) -> 3 | B5: 3 | C5: =IF(quotes_table[[#This Row],[ read_order]] = "","",INDEX(main_table[book_title],quotes_table[[#This Row],[ read_order]])) -> Ми, живі | D5: Хто страждає в цьому світі? Ті, кому чогось бракує? Ні, ті, хто мають таке, чого б їм ліпше бракувало.
A6: =IF(quotes_table[[#This Row],[ read_order]] = "","",INDEX(main_table[book_id],quotes_table[[#This Row],[ read_order]])) -> 3 | B6: 3 | C6: =IF(quotes_table[[#This Row],[ read_order]] = "","",INDEX(main_table[book_title],quotes_table[[#This Row],[ read_order]])) -> Ми, живі | D6: Коли нема апетиту до життя, то навіщо сідати до столу?
A7: =IF(quotes_table[[#This Row],[ read_order]] = "","",INDEX(main_table[book_id],quotes_table[[#This Row],[ read_order]])) -> 3 | B7: 3 | C7: =IF(quotes_table[[#This Row],[ read_order]] = "","",INDEX(main_table[book_title],quotes_table[[#This Row],[ read_order]])) -> Ми, живі | D7: Кожна чесна людина живе задля себе. А той, хто не живе для себе, - той узагалі не живе.
A8: =IF(quotes_table[[#This Row],[ read_order]] = "","",INDEX(main_table[book_id],quotes_table[[#This Row],[ read_order]])) -> 4 | B8: 4 | C8: =IF(quotes_table[[#This Row],[ read_order]] = "","",INDEX(main_table[book_title],quotes_table[[#This Row],[ read_order]])) -> The secret garden | D8: At first people refuse to believe that a strange new thing can be done, then they begin to hope it can be done, then they see it can be done—then it is done and all the world wonders why it was not done centuries ago.
A9: =IF(quotes_table[[#This Row],[ read_order]] = "","",INDEX(main_table[book_id],quotes_table[[#This Row],[ read_order]])) -> 4 | B9: 4 | C9: =IF(quotes_table[[#This Row],[ read_order]] = "","",INDEX(main_table[book_title],quotes_table[[#This Row],[ read_order]])) -> The secret garden | D9: Thought are as powerful as electric batteries - as good for one as sunlight is, or as bad for one as poison.
A10: =IF(quotes_table[[#This Row],[ read_order]] = "","",INDEX(main_table[book_id],quotes_table[[#This Row],[ read_order]])) -> 5 | B10: 5 | C10: =IF(quotes_table[[#This Row],[ read_order]] = "","",INDEX(main_table[book_title],quotes_table[[#This Row],[ read_order]])) -> Необхідне зло | D10: Істина та її наслідки - це дві різні речі. Істина не передбачає справедливості, як і високе походження не передбачає мудрості. Я знаю, що ваша душа прагне істини. Якщо доживете до справедливості, що ж, добре, якщо ні, то тому й бути. У будь-якому випадку справедливість може набувати різного вигляду.
A11: =IF(quotes_table[[#This Row],[ read_order]] = "","",INDEX(main_table[book_id],quotes_table[[#This Row],[ read_order]])) -> 6 | B11: 6 | C11: =IF(quotes_table[[#This Row],[ read_order]] = "","",INDEX(main_table[book_title],quotes_table[[#This Row],[ read_order]])) -> Незриме життя Адді Лярю | D11: Книжки дають змогу прожити тисячі життів - або знайти сили в одному, але дуже довгому.
A12: =IF(quotes_table[[#This Row],[ read_order]] = "","",INDEX(main_table[book_id],quotes_table[[#This Row],[ read_order]])) -> 6 | B12: 6 | C12: =IF(quotes_table[[#This Row],[ read_order]] = "","",INDEX(main_table[book_title],quotes_table[[#This Row],[ read_order]])) -> Незриме життя Адді Лярю | D12: На відміну від спогадів, ідеї такі сильні, що завжди прагнуть і шукають способу пустити коріння.
A13: =IF(quotes_table[[#This Row],[ read_order]] = "","",INDEX(main_table[book_id],quotes_table[[#This Row],[ read_order]])) -> 6 | B13: 6 | C13: =IF(quotes_table[[#This Row],[ read_order]] = "","",INDEX(main_table[book_title],quotes_table[[#This Row],[ read_order]])) -> Незриме життя Адді Лярю | D13: На кожну тінь знайдеться світло.
A14: =IF(quotes_table[[#This Row],[ read_order]] = "","",INDEX(main_table[book_id],quotes_table[[#This Row],[ read_order]])) -> 6 | B14: 6 | C14: =IF(quotes_table[[#This Row],[ read_order]] = "","",INDEX(main_table[book_title],quotes_table[[#This Row],[ read_order]])) -> Незриме життя Адді Лярю | D14: Навіть каміння стирається на порох.
A15: =IF(quotes_table[[#This Row],[ read_order]] = "","",INDEX(main_table[book_id],quotes_table[[#This Row],[ read_order]])) -> 8 | B15: 8 | C15: =IF(quotes_table[[#This Row],[ read_order]] = "","",INDEX(main_table[book_title],quotes_table[[#This Row],[ read_order]])) -> Дім голосів | D15: Ми пам'ятаємо минуле, щоб підготуватись до майбутнього.
A16: =IF(quotes_table[[#This Row],[ read_order]] = "","",INDEX(main_table[book_id],quotes_table[[#This Row],[ read_order]])) -> 8 | B16: 8 | C16: =IF(quotes_table[[#This Row],[ read_order]] = "","",INDEX(main_table[book_title],quotes_table[[#This Row],[ read_order]])) -> Дім голосів | D16: Іноді в нас є всі деталі, щоб збагнути правду, але ми просто не дуже хочемо її знати.
... A65: =IF(quotes_table[[#This Row],[ read_order]] = "","",INDEX(main_table[book_id],quotes_table[[#This Row],[ read_order]])) -> 40 | B65: 40 | C65: =IF(quotes_table[[#This Row],[ read_order]] = "","",INDEX(main_table[book_title],quotes_table[[#This Row],[ read_order]])) -> Доторк темряви | D65: У цьому й суть новин - завжди з'являється щось нове.
A66: =IF(quotes_table[[#This Row],[ read_order]] = "","",INDEX(main_table[book_id],quotes_table[[#This Row],[ read_order]])) -> 0 | B66: =ISTEXT(A66) -> 0 | C66: =IF(quotes_table[[#This Row],[ read_order]] = "","",INDEX(main_table[book_title],quotes_table[[#This Row],[ read_order]])) -> 0
A67: =IF(quotes_table[[#This Row],[ read_order]] = "","",INDEX(main_table[book_id],quotes_table[[#This Row],[ read_order]])) -> 0 | B67: =ISTEXT(A67) -> 0 | C67: =IF(quotes_table[[#This Row],[ read_order]] = "","",INDEX(main_table[book_title],quotes_table[[#This Row],[ read_order]])) -> 0
A68: =IF(quotes_table[[#This Row],[ read_order]] = "","",INDEX(main_table[book_id],quotes_table[[#This Row],[ read_order]])) -> 0 | B68: =ISTEXT(A68) -> 0 | C68: =IF(quotes_table[[#This Row],[ read_order]] = "","",INDEX(main_table[book_title],quotes_table[[#This Row],[ read_order]])) -> 0
A69: =IF(quotes_table[[#This Row],[ read_order]] = "","",INDEX(main_table[book_id],quotes_table[[#This Row],[ read_order]])) -> 0 | B69: =ISTEXT(A69) -> 0 | C69: =IF(quotes_table[[#This Row],[ read_order]] = "","",INDEX(main_table[book_title],quotes_table[[#This Row],[ read_order]])) -> 0
A70: =IF(quotes_table[[#This Row],[ read_order]] = "","",INDEX(main_table[book_id],quotes_table[[#This Row],[ read_order]])) -> 0 | B70: =ISTEXT(A70) -> 0 | C70: =IF(quotes_table[[#This Row],[ read_order]] = "","",INDEX(main_table[book_title],quotes_table[[#This Row],[ read_order]])) -> 0
A71: =IF(quotes_table[[#This Row],[ read_order]] = "","",INDEX(main_table[book_id],quotes_table[[#This Row],[ read_order]])) -> 0 | B71: =ISTEXT(A71) -> 0 | C71: =IF(quotes_table[[#This Row],[ read_order]] = "","",INDEX(main_table[book_title],quotes_table[[#This Row],[ read_order]])) -> 0
A72: =IF(quotes_table[[#This Row],[ read_order]] = "","",INDEX(main_table[book_id],quotes_table[[#This Row],[ read_order]])) -> 0 | B72: =ISTEXT(A72) -> 0 | C72: =IF(quotes_table[[#This Row],[ read_order]] = "","",INDEX(main_table[book_title],quotes_table[[#This Row],[ read_order]])) -> 0
A73: =IF(quotes_table[[#This Row],[ read_order]] = "","",INDEX(main_table[book_id],quotes_table[[#This Row],[ read_order]])) -> 0 | B73: =ISTEXT(A73) -> 0 | C73: =IF(quotes_table[[#This Row],[ read_order]] = "","",INDEX(main_table[book_title],quotes_table[[#This Row],[ read_order]])) -> 0
A74: =IF(quotes_table[[#This Row],[ read_order]] = "","",INDEX(main_table[book_id],quotes_table[[#This Row],[ read_order]])) -> 0 | B74: =ISTEXT(A74) -> 0 | C74: =IF(quotes_table[[#This Row],[ read_order]] = "","",INDEX(main_table[book_title],quotes_table[[#This Row],[ read_order]])) -> 0
A75: =IF(quotes_table[[#This Row],[ read_order]] = "","",INDEX(main_table[book_id],quotes_table[[#This Row],[ read_order]])) -> 0 | B75: =ISTEXT(A75) -> 0 | C75: =IF(quotes_table[[#This Row],[ read_order]] = "","",INDEX(main_table[book_title],quotes_table[[#This Row],[ read_order]])) -> 0
A76: =IF(quotes_table[[#This Row],[ read_order]] = "","",INDEX(main_table[book_id],quotes_table[[#This Row],[ read_order]])) -> 0 | B76: =ISTEXT(A76) -> 0 | C76: =IF(quotes_table[[#This Row],[ read_order]] = "","",INDEX(main_table[book_title],quotes_table[[#This Row],[ read_order]])) -> 0
A77: =IF(quotes_table[[#This Row],[ read_order]] = "","",INDEX(main_table[book_id],quotes_table[[#This Row],[ read_order]])) -> 0 | B77: =ISTEXT(A77) -> 0 | C77: =IF(quotes_table[[#This Row],[ read_order]] = "","",INDEX(main_table[book_title],quotes_table[[#This Row],[ read_order]])) -> 0
... A89: =IF(quotes_table[[#This Row],[ read_order]] = "","",INDEX(main_table[book_id],quotes_table[[#This Row],[ read_order]])) -> 0 | B89: =ISTEXT(A89) -> 0 | C89: =IF(quotes_table[[#This Row],[ read_order]] = "","",INDEX(main_table[book_title],quotes_table[[#This Row],[ read_order]])) -> 0

Sheet books_by_month
A1: month | B1: book_count | C1: days_read | D1: pages_read | H1: title_books_count_for_month | I1: result
A2: January | B2: =COUNTIF(book_raw!J:J, books_by_month[[#This Row],[month]]) -> 5 | C2: 25 | D2: =SUMIF(main_table[month_read],books_by_month[[#This Row],[month]],main_table[pages]) -> 1653 | H2: max_books_count_for_month | I2: =MAX(B2:B13) -> 17
A3: February | B3: =COUNTIF(book_raw!J:J, books_by_month[[#This Row],[month]]) -> 7 | C3: 26 | D3: =SUMIF(main_table[month_read],books_by_month[[#This Row],[month]],main_table[pages]) -> 2784 | H3: min_books_count_for_month | I3: =MIN(B2:B13) -> 4
A4: March | B4: =COUNTIF(book_raw!J:J, books_by_month[[#This Row],[month]]) -> 8 | C4: 30 | D4: =SUMIF(main_table[month_read],books_by_month[[#This Row],[month]],main_table[pages]) -> 2870 | H4: avr_books_count_for_month | I4: =AVERAGE(B2:B13) -> 9.1666667
A5: April | B5: =COUNTIF(book_raw!J:J, books_by_month[[#This Row],[month]]) -> 8 | C5: 26 | D5: =SUMIF(main_table[month_read],books_by_month[[#This Row],[month]],main_table[pages]) -> 3361
A6: May | B6: =COUNTIF(book_raw!J:J, books_by_month[[#This Row],[month]]) -> 6 | C6: 29 | D6: =SUMIF(main_table[month_read],books_by_month[[#This Row],[month]],main_table[pages]) -> 2236 | H6: title_days_read_for_month | I6: result
A7: June | B7: =COUNTIF(book_raw!J:J, books_by_month[[#This Row],[month]]) -> 10 | C7: 28 | D7: =SUMIF(main_table[month_read],books_by_month[[#This Row],[month]],main_table[pages]) -> 6593 | H7: max_days_read_for_month | I7: =MAX(C2:C13) -> 30
A8: July | B8: =COUNTIF(book_raw!J:J, books_by_month[[#This Row],[month]]) -> 9 | C8: 23 | D8: =SUMIF(main_table[month_read],books_by_month[[#This Row],[month]],main_table[pages]) -> 3312 | H8: min_days_read_for_month | I8: =MIN(C2:C13) -> 23
A9: August | B9: =COUNTIF(book_raw!J:J, books_by_month[[#This Row],[month]]) -> 4 | C9: 24 | D9: =SUMIF(main_table[month_read],books_by_month[[#This Row],[month]],main_table[pages]) -> 1600 | H9: avr_days_read_for_month | I9: =AVERAGE(C2:C13) -> 26.75
A10: September | B10: =COUNTIF(book_raw!J:J, books_by_month[[#This Row],[month]]) -> 17 | C10: 27 | D10: =SUMIF(main_table[month_read],books_by_month[[#This Row],[month]],main_table[pages]) -> 6039
A11: October | B11: =COUNTIF(book_raw!J:J, books_by_month[[#This Row],[month]]) -> 10 | C11: 27 | D11: =SUMIF(main_table[month_read],books_by_month[[#This Row],[month]],main_table[pages]) -> 3347 | H11: title_pages_for_month | I11: result
A12: November | B12: =COUNTIF(book_raw!J:J, books_by_month[[#This Row],[month]]) -> 15 | C12: 30 | D12: =SUMIF(main_table[month_read],books_by_month[[#This Row],[month]],main_table[pages]) -> 4424 | H12: max_pages_for_month | I12: =MAX(D2:D13) -> 6593
A13: December | B13: =COUNTIF(book_raw!J:J, books_by_month[[#This Row],[month]]) -> 11 | C13: 26 | D13: =SUMIF(main_table[month_read],books_by_month[[#This Row],[month]],main_table[pages]) -> 3562 | H13: min_pages_for_month | I13: =MIN(D2:D13) -> 1600
A14: Total | B14: =SUBTOTAL(109,B2:B13) -> 110 | C14: =SUBTOTAL(109,C2:C13) -> 321 | D14: =SUBTOTAL(109,D2:D13) -> 41781 | H14: avr_pages_for_month | I14: =AVERAGE(D2:D13) -> 3481.75

Sheet summary_2025
A1: Metric | B1: Count
A2: Total books | B2: =COUNTA(book_raw!A1:A111)-1 -> 110
A3: Total pages | B3: =SUM(book_raw!I1:I111,) -> 41781
A4: Print books | B4: =COUNTIF(book_raw!G1:G111,"Print") -> 26
A5: Ebooks | B5: =COUNTIF(book_raw!G1:G111,"Ebook") -> 32
A6: Audiobooks | B6: =COUNTIF(book_raw!G1:G111,"Audio") -> 52
A7: Top books | B7: =COUNTIF(book_raw!Q1:Q111,"+") -> 30
A8: Books with quotes | B8: =COUNTIF(book_raw!P1:P111,"yes") -> 45

Sheet book_series
A1: Row Labels | B1: Count of book_id
A2: Агенція "Локвуд і Ко" | B2: 5
A3: Варта у грі | B3: 1
A4: Гадес і Персефона | B4: 4
A5: Ганнібал Лектер | B5: 4
A6: Гаррі Поттер (фанфік) | B6: 2
A7: Девід Хантер | B7: 2
A8: Емпіреї | B8: 2
A9: капітан Віндгем та сержант Бенерджі | B9: 4
A10: Міккі 7 | B10: 2
A11: Персі Джексон і боги-олімпійці | B11: 3
A12: Плоть і вогонь | B12: 1
A13: Попіл лине до неба | B13: 1
... A19: Grand Total | B19: 48

Sheet book_series_all
A1: series_name | B1: total_books_in_series | C1: books_read | D1: left_to_read | E1: actual_start_2025 | F1: status
A2: Агенція "Локвуд і Ко" | B2: 5 | C2: 5 | D2: =book_series_all_table[[#This Row],[total_books_in_series]] - book_series_all_table[[#This Row],[books_read]] -> 0 | E2: 1 | F2: =IF(book_series_all_table[[#This Row],[left_to_read]]=0,"completed","in progress") -> completed
A3: Варта у грі | B3: 3 | C3: 1 | D3: =book_series_all_table[[#This Row],[total_books_in_series]] - book_series_all_table[[#This Row],[books_read]] -> 2 | E3: 1 | F3: =IF(book_series_all_table[[#This Row],[left_to_read]]=0,"completed","in progress") -> in progress
A4: Гадес і Персефона | B4: 7 | C4: 4 | D4: =book_series_all_table[[#This Row],[total_books_in_series]] - book_series_all_table[[#This Row],[books_read]] -> 3 | E4: 1 | F4: =IF(book_series_all_table[[#This Row],[left_to_read]]=0,"completed","in progress") -> in progress
A5: Ганнібал Лектер | B5: 4 | C5: 4 | D5: =book_series_all_table[[#This Row],[total_books_in_series]] - book_series_all_table[[#This Row],[books_read]] -> 0 | E5: 1 | F5: =IF(book_series_all_table[[#This Row],[left_to_read]]=0,"completed","in progress") -> completed
A6: Гаррі Поттер (фанфік) | B6: 6 | C6: 2 | D6: =book_series_all_table[[#This Row],[total_books_in_series]] - book_series_all_table[[#This Row],[books_read]] -> 4 | E6: 1 | F6: =IF(book_series_all_table[[#This Row],[left_to_read]]=0,"completed","in progress") -> in progress
A7: Девід Хантер | B7: 6 | C7: 2 | D7: =book_series_all_table[[#This Row],[total_books_in_series]] - book_series_all_table[[#This Row],[books_read]] -> 4 | E7: 5 | F7: =IF(book_series_all_table[[#This Row],[left_to_read]]=0,"completed","in progress") -> in progress
A8: Емпіреї | B8: 3 | C8: 2 | D8: =book_series_all_table[[#This Row],[total_books_in_series]] - book_series_all_table[[#This Row],[books_read]] -> 1 | E8: 1 | F8: =IF(book_series_all_table[[#This Row],[left_to_read]]=0,"completed","in progress") -> in progress
A9: капітан Віндгем та сержант Бенерджі | B9: 5 | C9: 4 | D9: =book_series_all_table[[#This Row],[total_books_in_series]] - book_series_all_table[[#This Row],[books_read]] -> 1 | E9: 2 | F9: =IF(book_series_all_table[[#This Row],[left_to_read]]=0,"completed","in progress") -> in progress
A10: Міккі 7 | B10: 2 | C10: 2 | D10: =book_series_all_table[[#This Row],[total_books_in_series]] - book_series_all_table[[#This Row],[books_read]] -> 0 | E10: 1 | F10: =IF(book_series_all_table[[#This Row],[left_to_read]]=0,"completed","in progress") -> completed
A11: Персі Джексон і боги-олімпійці | B11: 5 | C11: 3 | D11: =book_series_all_table[[#This Row],[total_books_in_series]] - book_series_all_table[[#This Row],[books_read]] -> 2 | E11: 1 | F11: =IF(book_series_all_table[[#This Row],[left_to_read]]=0,"completed","in progress") -> in progress
A12: Плоть і вогонь | B12: 4 | C12: 1 | D12: =book_series_all_table[[#This Row],[total_books_in_series]] - book_series_all_table[[#This Row],[books_read]] -> 3 | E12: 2 | F12: =IF(book_series_all_table[[#This Row],[left_to_read]]=0,"completed","in progress") -> in progress
A13: Попіл лине до неба | B13: 2 | C13: 1 | D13: =book_series_all_table[[#This Row],[total_books_in_series]] - book_series_all_table[[#This Row],[books_read]] -> 1 | E13: 1 | F13: =IF(book_series_all_table[[#This Row],[left_to_read]]=0,"completed","in progress") -> in progress
... A18: Хроніки Нарнії | B18: 7 | C18: 7 | D18: =book_series_all_table[[#This Row],[total_books_in_series]] - book_series_all_table[[#This Row],[books_read]] -> 0 | E18: 1 | F18: =IF(book_series_all_table[[#This Row],[left_to_read]]=0,"completed","in progress") -> completed
